<?xml version="1.0"?>
<robot xmlns:xacro="http://www.ros.org/wiki/xacro" name="kr16_macro">
  <xacro:macro name="kr16" params="prefix:='kr16_' connected_to:='' xyz:='0 0 0' rpy:='0 0 0'">
    <!-- LINKS -->
    <!-- base link -->
    <link name="${prefix}base_link">
      <visual>
        <origin xyz="0 0 0" rpy="0 0 0"/>
        <geometry>
          <mesh filename="package://kuka_kr_description/meshes/kr16/visual/base_link.dae" />
        </geometry>
      </visual>
    </link>
    <!-- link 1 (A1) -->
    <link name="${prefix}link_1">
      <visual>
        <origin xyz="0 0 0" rpy="0 0 0"/>
        <geometry>
          <mesh filename="package://kuka_kr_description/meshes/kr16/visual/link_1.dae" />
        </geometry>
      </visual>
    </link>
    <!-- link 2 -->
    <link name="${prefix}link_2">
      <visual>
        <origin xyz="0 0 0" rpy="0 0 0"/>
        <geometry>
          <mesh filename="package://kuka_kr_description/meshes/kr16/visual/link_2.dae"/>
        </geometry>
      </visual>
    </link>
    <!-- link 3 -->
    <link name="${prefix}link_3">
      <visual>
        <origin xyz="0 0 0" rpy="0 0 0"/>
        <geometry>
          <mesh filename="package://kuka_kr_description/meshes/kr16/visual/link_3.dae" />
        </geometry>
      </visual>
    </link>
    <!-- link 4 -->
    <link name="${prefix}link_4">
      <visual>
        <origin xyz="0 0 0" rpy="0 0 0"/>
        <geometry>
          <mesh filename="package://kuka_kr_description/meshes/kr16/visual/link_4.dae" />
        </geometry>
      </visual>
    </link>
    <!-- link 5 -->
    <link name="${prefix}link_5">
      <visual>
        <origin xyz="0 0 0" rpy="0 0 0"/>
        <geometry>
          <mesh filename="package://kuka_kr_description/meshes/kr16/visual/link_5.dae" />
        </geometry>
      </visual>
    </link>
    <!-- link 6 -->
    <link name="${prefix}link_6">
      <visual>
        <origin xyz="0 0 0" rpy="0 0 0"/>
        <geometry>
          <mesh filename="package://kuka_kr_description/meshes/kr16/visual/link_6.dae" />
        </geometry>
      </visual>
    </link>
    <!-- tool 0 -->
    <!-- Following REP199, this frame shall be use to attach EEF or other equipment -->
    <link name="${prefix}flange" />
    <!-- END LINKS -->

    <!-- JOINTS -->
    <!-- joint 1 (A1) -->
    <joint name="${prefix}joint_a1" type="revolute">
      <origin xyz="0 0 0.52" rpy="0 0 0"/>
      <parent link="${prefix}base_link"/>
      <child link="${prefix}link_1"/>
      <axis xyz="0 0 -1"/>
      <limit effort="0" lower="${radians(-185)}" upper="${radians(185)}" velocity="${radians(200)}"/>
    </joint>
    <!-- joint 2 (A2) -->
    <joint name="${prefix}joint_a2" type="revolute">
      <origin xyz="0.16 0 0" rpy="0 0 0"/>
      <parent link="${prefix}link_1"/>
      <child link="${prefix}link_2"/>
      <axis xyz="0 1 0"/>
      <limit effort="0" lower="${radians(-185)}" upper="${radians(65)}" velocity="${radians(175)}"/>
    </joint>
    <!-- joint 3 (A3) -->
    <joint name="${prefix}joint_a3" type="revolute">
      <origin xyz="0.78 0 0" rpy="0 0 0"/>
      <parent link="${prefix}link_2"/>
      <child link="${prefix}link_3"/>
      <axis xyz="0 1 0"/>
      <limit effort="0" lower="${radians(-138)}" upper="${radians(175)}" velocity="${radians(190)}"/>
    </joint>
    <!-- joint 4 (A4) -->
    <joint name="${prefix}joint_a4" type="revolute">
      <origin xyz="0.655 0 0.15" rpy="0 0 0"/>
      <parent link="${prefix}link_3"/>
      <child link="${prefix}link_4"/>
      <axis xyz="-1 0 0"/>
      <limit effort="0" lower="${radians(-350)}" upper="${radians(350)}" velocity="${radians(430)}"/>
    </joint>
    <!-- joint 5 (A5) -->
    <joint name="${prefix}joint_a5" type="revolute">
      <origin xyz="0 0 0" rpy="0 0 0"/>
      <parent link="${prefix}link_4"/>
      <child link="${prefix}link_5"/>
      <axis xyz="0 1 0"/>
      <limit effort="0" lower="${radians(-130)}" upper="${radians(130)}" velocity="${radians(430)}"/>
    </joint>
    <!-- joint 6 (A6) -->
    <joint name="${prefix}joint_a6" type="revolute">
      <origin xyz="0 0 0" rpy="0 0 0"/>
      <parent link="${prefix}link_5"/>
      <child link="${prefix}link_6"/>
      <axis xyz="-1 0 0"/>
      <limit effort="0" lower="${radians(-350)}" upper="${radians(350)}" velocity="${radians(630)}"/>
    </joint>
    <!-- tool frame - fixed frame -->
    <joint name="${prefix}joint_a6-flange" type="fixed">
      <parent link="${prefix}link_6"/>
      <child link="${prefix}flange"/>
      <origin xyz="0.153 0 0" rpy="0 0 0"/>
    </joint>
    <!-- END JOINTS -->

    <xacro:if value="${connected_to == ''}">
      <xacro:property name="base_frame_name" value="world"/>
    </xacro:if>
    <xacro:unless value="${connected_to == ''}">
      <xacro:property name="base_frame_name" value="${connected_to}"/>
    </xacro:unless>
    <link name="${base_frame_name}"/>
    <joint name="${base_frame_name}-${prefix}base_link" type="fixed">
      <origin xyz="${xyz}" rpy="${rpy}"/>
      <parent link="${base_frame_name}"/>
      <child link="${prefix}base_link"/>
    </joint>

    <!-- ROS base_link to KUKA $ROBROOT coordinate system transform -->
    <link name="${prefix}base" />
    <joint name="${prefix}base_link-base" type="fixed">
      <origin xyz="0 0 0" rpy="0 0 0"/>
      <parent link="${prefix}base_link"/>
      <child link="${prefix}base"/>
    </joint>

    <!-- This frame corresponds to the $TOOL coordinate system in KUKA KRC controllers -->
    <link name="${prefix}tool0" />
    <joint name="${prefix}flange-tool0" type="fixed">
      <parent link="${prefix}flange"/>
      <child link="${prefix}tool0"/>
      <origin xyz="0 0 0" rpy="0 ${radians(90)} 0"/>
    </joint>

  </xacro:macro>
</robot>
